<?xml version="1.0" ?>
<!-- =================================================================================== -->
<!-- |    This document was autogenerated by xacro from /home/keerthivasan/keerthi/ws_isro/src/b47/b47_description/urdf/b47.xacro | -->
<!-- |    EDITING THIS FILE BY HAND IS NOT RECOMMENDED                                 | -->
<!-- =================================================================================== -->
<robot name="b47">
    <link name="base_link">
        <inertial>
            <origin rpy="0.0 0.0 0.0" xyz="0.0 0.0 0.1" />
            <mass value="2" />
            <inertia ixx="0.05166666666666667" ixy="0.0" ixz="0.0" iyy="0.05166666666666667" iyz="0.0" izz="0.09" />
        </inertial>
        <visual>
            <origin rpy="0.0 0.0 0.0" xyz="0.0 0.0 0.1" />
            <geometry>
                <cylinder length="0.2" radius="0.30" />
            </geometry>
        </visual>
        <collision>
            <origin rpy="0.0 0.0 0.0" xyz="0.0 0.0 0.1" />
            <geometry>
                <cylinder length="0.2" radius="0.30" />
            </geometry>
        </collision>
    </link>
    <link name="link_01">
        <inertial>
            <origin rpy="0.0 0.0 0.0" xyz="0.0 0.0 0.2" />
            <mass value="3" />
            <inertia ixx="0.08687500000000001" ixy="0.0" ixz="0.0" iyy="0.08687500000000001" iyz="0.0" izz="0.09375" />
        </inertial>
        <visual>
            <origin rpy="0.0 0.0 0.0" xyz="0.0 0.0 0.2" />
            <geometry>
                <cylinder length="0.4" radius="0.25" />
            </geometry>
        </visual>
        <collision>
            <origin rpy="0.0 0.0 0.0" xyz="0.0 0.0 0.2" />
            <geometry>
                <cylinder length="0.4" radius="0.25" />
            </geometry>
        </collision>
    </link>
    <joint name="base_link_link_01" type="revolute">
        <parent link="base_link" />
        <child link="link_01" />
        <axis xyz="0 0 1" />
        <limit effort="30000.0" lower="-3.14159" upper="3.14159" velocity="2.0" />
        <origin rpy="0 0 0" xyz="0 0 0.2" />
    </joint>
    <link name="link_02">
        <inertial>
            <origin rpy="0.0 0.0 0.0" xyz="0.0 0.0 0.4" />
            <mass value="3" />
            <inertia ixx="0.17687500000000003" ixy="0.0" ixz="0.0" iyy="0.17687500000000003" iyz="0.0" izz="0.03375" />
        </inertial>
        <visual>
            <origin rpy="0.0 0.0 0" xyz="0.0 0.0 0.4" />
            <geometry>
                <cylinder length="0.8" radius="0.15" />
            </geometry>
        </visual>
        <collision>
            <origin rpy="0.0 0.0 0.0" xyz="0.0 0.0 0.4" />
            <geometry>
                <cylinder length="0.8" radius="0.15" />
            </geometry>
        </collision>
    </link>
    <joint name="link_01_link_02" type="revolute">
        <parent link="link_01" />
        <child link="link_02" />
        <axis xyz="0 1 0" />
        <limit effort="30000.0" lower="-3.14159" upper="3.14159" velocity="2.0" />
        <origin rpy="0 0 0" xyz="0 0 0.4" />
    </joint>
    <link name="link_03">
        <inertial>
            <origin rpy="0.0 0.0 0.0" xyz="0.0 0.0 0.4" />
            <mass value="3" />
            <inertia ixx="0.17687500000000003" ixy="0.0" ixz="0.0" iyy="0.17687500000000003" iyz="0.0" izz="0.03375" />
        </inertial>
        <visual>
            <origin rpy="0.0 0.0 0" xyz="0.0 0.0 0.4" />
            <geometry>
                <cylinder length="0.8" radius="0.15" />
            </geometry>
        </visual>
        <collision>
            <origin rpy="0.0 0.0 0.0" xyz="0.0 0.0 0.4" />
            <geometry>
                <cylinder length="0.8" radius="0.15" />
            </geometry>
        </collision>
    </link>
    <joint name="link_02_link_03" type="revolute">
        <parent link="link_02" />
        <child link="link_03" />
        <axis xyz="0 1 0" />
        <limit effort="30000.0" lower="-3.14159" upper="3.14159" velocity="2.0" />
        <origin rpy="0 0 0" xyz="0 0 0.8" />
    </joint>
    <link name="link_04">
        <inertial>
            <origin rpy="0.0 0.0 0.0" xyz="0.0 0.0 0.2" />
            <mass value="3" />
            <inertia ixx="0.08687500000000001" ixy="0.0" ixz="0.0" iyy="0.08687500000000001" iyz="0.0" izz="0.09375" />
        </inertial>
        <visual>
            <origin rpy="0.0 0.0 0.0" xyz="0.0 0.0 0.2" />
            <geometry>
                <cylinder length="0.4" radius="0.25" />
            </geometry>
        </visual>
        <collision>
            <origin rpy="0.0 0.0 0.0" xyz="0.0 0.0 0.2" />
            <geometry>
                <cylinder length="0.4" radius="0.25" />
            </geometry>
        </collision>
    </link>
    <joint name="link_03_link_04" type="revolute">
        <parent link="link_03" />
        <child link="link_04" />
        <axis xyz="0 1 0" />
        <limit effort="30000.0" lower="-3.14159" upper="3.14159" velocity="2.0" />
        <origin rpy="0 0 0" xyz="0 0 0.8" />
    </joint>
    <link name="link_05">
        <inertial>
            <origin rpy="0.0 0.0 0.0" xyz="0.0 0.0 0.1" />
            <mass value="2" />
            <inertia ixx="0.05166666666666667" ixy="0.0" ixz="0.0" iyy="0.05166666666666667" iyz="0.0" izz="0.09" />
        </inertial>
        <visual>
            <origin rpy="0.0 0.0 0.0" xyz="0.0 0.0 0.1" />
            <geometry>
                <cylinder length="0.2" radius="0.30" />
            </geometry>
        </visual>
        <collision>
            <origin rpy="0.0 0.0 0.0" xyz="0.0 0.0 0.1" />
            <geometry>
                <cylinder length="0.2" radius="0.30" />
            </geometry>
        </collision>
    </link>
    <joint name="link_04_link_05" type="revolute">
        <parent link="link_04" />
        <child link="link_05" />
        <axis xyz="0 0 1" />
        <limit effort="30000.0" lower="-3.14159" upper="3.14159" velocity="2.0" />
        <origin rpy="0 0 0" xyz="0 0 0.4" />
    </joint>
    <transmission name="trans_base_link_link_01">
        <type>transmission_interface/SimpleTransmission</type>
        <joint name="base_link_link_01">
            <hardwareInterface>hardware_interface/EffortJointInterface</hardwareInterface>
        </joint>
        <actuator name="motor_base_link_link_01">
            <mechanicalReduction>1.0</mechanicalReduction>
            <hardwareInterface>hardware_interface/EffortJointInterface</hardwareInterface>
        </actuator>
    </transmission>
    <transmission name="trans_link_01_link_02">
        <type>transmission_interface/SimpleTransmission</type>
        <joint name="link_01_link_02">
            <hardwareInterface>hardware_interface/EffortJointInterface</hardwareInterface>
        </joint>
        <actuator name="motor_link_01_link_02">
            <mechanicalReduction>1.0</mechanicalReduction>
            <hardwareInterface>hardware_interface/EffortJointInterface</hardwareInterface>
        </actuator>
    </transmission>
    <transmission name="trans_link_02_link_03">
        <type>transmission_interface/SimpleTransmission</type>
        <joint name="link_02_link_03">
            <hardwareInterface>hardware_interface/EffortJointInterface</hardwareInterface>
        </joint>
        <actuator name="motor_link_02_link_03">
            <mechanicalReduction>1.0</mechanicalReduction>
            <hardwareInterface>hardware_interface/EffortJointInterface</hardwareInterface>
        </actuator>
    </transmission>
    <transmission name="trans_link_03_link_04">
        <type>transmission_interface/SimpleTransmission</type>
        <joint name="link_03_link_04">
            <hardwareInterface>hardware_interface/EffortJointInterface</hardwareInterface>
        </joint>
        <actuator name="motor_link_03_link_04">
            <mechanicalReduction>1.0</mechanicalReduction>
            <hardwareInterface>hardware_interface/EffortJointInterface</hardwareInterface>
        </actuator>
    </transmission>
    <transmission name="trans_link_04_link_05">
        <type>transmission_interface/SimpleTransmission</type>
        <joint name="link_04_link_05">
            <hardwareInterface>hardware_interface/EffortJointInterface</hardwareInterface>
        </joint>
        <actuator name="motor_link_04_link_05">
            <mechanicalReduction>1.0</mechanicalReduction>
            <hardwareInterface>hardware_interface/EffortJointInterface</hardwareInterface>
        </actuator>
    </transmission>
    <gazebo>
        <plugin filename="libgazebo_ros_control.so" name="gazebo_ros_control">
            <robotNamespace>/</robotNamespace>
        </plugin>
    </gazebo>
</robot>

